<?xml version="1.0"?>
<robot name="sdv_car" xmlns:xacro="http://www.ros.org/wiki/xacro">

<!-- 
  <xacro:property name="tire_dia" value="0.750"/> 
  <xacro:property name="tire_width" value="0.125"/>  
  <xacro:property name="hub_dia" value="0.235"/>   -->

  <xacro:property name="tire_dia" value="0.750"/>  <!-- Reduced from 0.440 -->
  <xacro:property name="tire_width" value="0.195"/>  <!-- Reduced from 0.195 -->
  <xacro:property name="hub_dia" value="0.235"/>  <!-- Reduced from 0.235 -->

  <xacro:property name="hex_hub_depth" value="0.120"/> <!-- or +0.072 -->  
  <xacro:property name="wheel_mass" value="8.0"/>   <!-- check -->


  <xacro:property name="wheelbase" value="2.1"/>
  <xacro:property name="hex_hub_dist" value="0.9191"/> 
  <xacro:property name="wheel_travel" value="0.209492959255614"/> 

  <xacro:property name="axle_eff_limit" value="204.95"/>
  <xacro:property name="axle_vel_limit" value="39.02"/>


  

  <!-- Properties of the car -->
  <xacro:property name="front_wheel_x" value="0.087346576344423"/>
  <xacro:property name="front_wheel_y" value="0.695625727164768"/>
  <xacro:property name="front_wheel_z" value="0.2594929592556163"/>

  <xacro:property name="rear_wheel_x" value="-2.04780116842239"/>
  <xacro:property name="rear_wheel_y" value="0.695625727164768"/>
  <xacro:property name="rear_wheel_z" value="0.2594929592556163"/>

  <!-- Degree-to-radian conversions -->
  <xacro:property name="degrees_45" value="0.785398163"/>
  <xacro:property name="degrees_90" value="1.57079633"/>
  <xacro:property name="degrees_180" value="3.14159265"/>

  <xacro:property name="servo_stall_torque" value="50"/>  <!-- check -->
  <xacro:property name="servo_no_load_speed" value="25"/> <!-- check -->

  <material name="black">
      <color rgba="0 0 0 1"/>
  </material>

  <xacro:macro name="thick_walled_tube_inertial"
               params="inner_rad outer_rad height mass">
    <inertial>
      <mass value="${mass}"/>
      <inertia ixx="${(1 / 12) * mass * (3 * (inner_rad * inner_rad +
                    outer_rad * outer_rad) + height * height)}"
               ixy="0" ixz="0"
               iyy="${(1 / 12) * mass * (3 * (inner_rad * inner_rad +
                    outer_rad * outer_rad) + height * height)}"
               iyz="0"
               izz="${mass * (inner_rad * inner_rad +
                    outer_rad * outer_rad) / 2}"/>
    </inertial>
  </xacro:macro>

  <xacro:macro name="null_inertial">
    <inertial>
      <mass value="4.5"/>
      <inertia ixx="0.001" ixy="0" ixz="0" iyy="0.001" iyz="0" izz="0.001"/>
    </inertial>
  </xacro:macro>

  <!-- front wheel -->
  <xacro:macro name="front_wheel" params="lr_prefix fr_prefix lr_reflect">

    <link name="${lr_prefix}_steering_link">

      <xacro:null_inertial/>

      <!-- <xacro:thick_walled_tube_inertial
          inner_rad="${hub_dia / 2}" outer_rad="${tire_dia / 2}"
          height="${tire_width}" mass="${wheel_mass}"/> -->

    </link>

    <joint name="${lr_prefix}_steering_joint" type="revolute">

      <origin xyz="${fr_reflect * front_wheel_x} ${lr_reflect * front_wheel_y} ${-front_wheel_z}" rpy="0 ${degrees_90} 0"/>

      <parent link="base_link"/>
      <child link="${lr_prefix}_steering_link"/>
      <axis xyz="-1 0 0"/>
      <limit lower="${-degrees_45}" upper="${degrees_45}"
            effort="${servo_stall_torque}" velocity="${servo_no_load_speed}"/>
    </joint>


    <link name="${lr_prefix}_${fr_prefix}_wheel">
      <visual>
        <origin xyz="0
                     0
                     ${lr_reflect * ((tire_width / 2 - hex_hub_depth))}" rpy="0 0 0"/>
        <geometry>
          <cylinder radius="${tire_dia / 2}" length="${tire_width}"/>
        </geometry>
        <material name="black" />


      </visual>

      <collision>
        <origin xyz="0                     
                     0
                     ${lr_reflect * ((tire_width / 2 - hex_hub_depth))}" rpy="0 0 0"/>
        <geometry>
          <cylinder radius="${tire_dia / 2}" length="${tire_width}"/>
        </geometry>
      </collision>

      <xacro:thick_walled_tube_inertial
          inner_rad="${hub_dia / 2}" outer_rad="${tire_dia / 2}"
          height="${tire_width}" mass="${wheel_mass}"/>
    </link>


    <joint name="${lr_prefix}_${fr_prefix}_axle" type="continuous">
      <parent link="${lr_prefix}_steering_link"/>
      <child link="${lr_prefix}_${fr_prefix}_wheel"/>
      <origin xyz="0 0 0" rpy="1.5708 0 0" />
      <axis xyz="0 0 -1"/>
      <limit effort="${axle_eff_limit}" velocity="${axle_vel_limit}"/>
    </joint>

    <gazebo reference="${lr_prefix}_${fr_prefix}_wheel">
      <material>Gazebo/Black</material>
    </gazebo>
        

    


  </xacro:macro>


  <!-- rear wheel -->
  <xacro:macro name="rear_wheel" params="lr_prefix fr_prefix lr_reflect">


    <link name="${lr_prefix}_${fr_prefix}_wheel">
      <visual>
        <origin xyz="0
                     0
                     ${lr_reflect * ((tire_width / 2 - hex_hub_depth))}" rpy="0 0 0"/>
        <geometry>
          <cylinder radius="${tire_dia / 2}" length="${tire_width}"/>
        </geometry>
        <material name="black" />
      </visual>

      <collision>
        <origin xyz="0                     
                     0
                     ${lr_reflect * ((tire_width / 2 - hex_hub_depth))}" rpy="0 0 0"/>
        <geometry>
          <cylinder radius="${tire_dia / 2}" length="${tire_width}"/>
        </geometry>
      </collision>

      <xacro:thick_walled_tube_inertial
          inner_rad="${hub_dia / 2}" outer_rad="${tire_dia / 2}"
          height="${tire_width}" mass="${wheel_mass}"/>
    </link>


    <joint name="${lr_prefix}_${fr_prefix}_axle" type="continuous">
      <parent link="base_link"/>
      <child link="${lr_prefix}_${fr_prefix}_wheel"/>
      <origin xyz="${fr_reflect * rear_wheel_x} ${lr_reflect * rear_wheel_y} ${-rear_wheel_z}" rpy="1.5708 0 0"/>
      <axis xyz="0 0 -1"/>
      <limit effort="${axle_eff_limit}" velocity="${axle_vel_limit}"/>
    </joint>

    <gazebo reference="${lr_prefix}_${fr_prefix}_wheel">
      <material>Gazebo/Black</material>
    </gazebo>

  </xacro:macro>



    <xacro:macro name="front_wheel_to_base" params="lr_prefix fr_prefix lr_reflect fr_reflect">
      
      <xacro:front_wheel lr_prefix="${lr_prefix}" fr_prefix="${fr_prefix}" lr_reflect="${lr_reflect}"/>

    </xacro:macro>

    <xacro:macro name="rear_wheel_to_base" params="lr_prefix fr_prefix lr_reflect fr_reflect">
        <xacro:rear_wheel lr_prefix="${lr_prefix}" fr_prefix="${fr_prefix}" lr_reflect="${lr_reflect}"/>
    </xacro:macro>

  

</robot>